---
title: 'DynamoDBエラー [The provided key element does not match the schema]'
tags:
  - DynamoDB
private: false
updated_at: '2022-01-25T23:29:00+09:00'
id: 51e6a1af9b241f499747
organization_url_name: null
slide: false
ignorePublish: false
---
# エラー
LambdaからDynamoDBを呼び出す際、get_item(Key={UniqueId: 'UniqueId'})した時にでたエラー。
内容的にkeyのtypeが違うのかと思っていたらソートキーを指定しないといけなかったよう。。。

```bash
[ERROR] ClientError: An error occurred (ValidationException) when calling the GetItem operation: The provided key element does not match the schema
```

# 解決法
ソートキーを指定するもしくはDBのソートキーを指定しない。




```python
dynamodb = boto3.resource('dynamodb')
table = dynamodb.Table('テーブル')
res = table.get_item(Key={
            'UniqueId': 'UniqueId',
            'SortKey': 'SortKey'
        })
```







