---
title: <firebase functions> custom errorを投げる
tags:
  - Node.js
  - Firebase
private: false
updated_at: '2023-08-13T21:46:35+09:00'
id: 859e403953c0713254fe
organization_url_name: null
slide: false
ignorePublish: false
---
firebase functions でオリジナルのエラーを投げたい場面。

自前でerrorを返しても常にinternalエラーが返ってきてしまう

```js
[admin.FirebaseError: internal] {
   code: 'functions/internal',
   customData: undefined,
   name: 'FirebaseError',
   details: undefined
 }
```


```js
functions.https.onRequest(async (req, res): Promise<void> => {
  res.status(200).send({message: 'error'});
}
```

```js
functions.https.onRequest(async (req, res): Promise<void> => {
  res.status(500).send({message: 'error'});
}
```

# 解決法
今回は以下の2stepで行いました
1. 関数の定義をonCallにする
1. https.errorをthrowする

:::note
onCall は firebase sdkで呼び出す時のみ。
corsや認証の対応が楽にできる。
:::

```js
import { https } from 'firebase-functions';

functions.https.onCall(async (data, context): Promise<void> => {  
// do some
...

// error handling
throw new https.HttpsError('<定義されているcode>', '<custom message>')
}
```

# 参考
https://medium.com/geekculture/how-to-pass-errors-nicely-to-front-end-with-firebase-cloud-functions-6f224072eae4

https://azukiazusa.dev/blog/firebase-functions-https-oncall/
